Exception during training: Target size (torch.Size([256, 86])) must be the same as input size (torch.Size([244, 86]))
Traceback (most recent call last):
  File "/home/rogia/Documents/git/invivoprojects/side_effects/bin/train", line 35, in main
    input_path=input_path)
  File "/home/rogia/Documents/git/invivoprojects/side_effects/side_effects/utils.py", line 135, in run_experiment
    with_early_stopping=early_stopping)
  File "/home/rogia/Documents/git/invivoprojects/side_effects/side_effects/models/model.py", line 148, in train
    epochs=n_epochs, callbacks=callbacks)
  File "/home/rogia/miniconda3/envs/invivo/lib/python3.6/site-packages/pytoune/framework/model.py", line 310, in fit_generator
    step=step.number)
  File "/home/rogia/miniconda3/envs/invivo/lib/python3.6/site-packages/pytoune/framework/model.py", line 325, in _fit_batch
    x, y, return_loss_tensor=True, return_pred=return_pred
  File "/home/rogia/miniconda3/envs/invivo/lib/python3.6/site-packages/pytoune/framework/model.py", line 601, in _compute_loss_and_metrics
    loss = self.loss_function(pred_y, y)
  File "/home/rogia/miniconda3/envs/invivo/lib/python3.6/site-packages/torch/nn/modules/module.py", line 477, in __call__
    result = self.forward(*input, **kwargs)
  File "/home/rogia/miniconda3/envs/invivo/lib/python3.6/site-packages/torch/nn/modules/loss.py", line 573, in forward
    reduction=self.reduction)
  File "/home/rogia/miniconda3/envs/invivo/lib/python3.6/site-packages/torch/nn/functional.py", line 1646, in binary_cross_entropy_with_logits
    raise ValueError("Target size ({}) must be the same as input size ({})".format(target.size(), input.size()))
ValueError: Target size (torch.Size([256, 86])) must be the same as input size (torch.Size([244, 86]))
